если применён catch, то данные об ошибке будут попадать в блок next, а не в блок error.
при этом можно  catch помещать в .pipe()

// вывод ошибки в error
const source = Rx.Observable.throw('This is an error!');
const subscribe = source.subscribe(
	val => console.log(val),
  	error => console.log('errr', error)
);

// вывод ошибки в next
const source = Rx.Observable.throw('This is an error!');
const example = source.catch(val => Rx.Observable.of(`I caught: ${val}`));
const subscribe = example.subscribe(val => console.log(val));

// тоже вывод ошибки в next, но с использование .pipe()
const source = throwError('This is an error!');
const example = source.pipe(catchError(val => of(`I caught: ${val}`)));
const subscribe = example.subscribe(val => console.log(val));


=========================
=========================
=========================
=========================
=========================
=========================
=========================
=========================
=========================
=========================
=========================